<?xml version='1.0'?>
<sdf version='1.4'>
  <model name='valve'>
    <static>false</static>
    <link name='wheel'>
      <pose>0 0 0.07 0 0 0</pose>

      <inertial>
        <pose>0 0 0.15 0 0 0</pose>
        <mass>3.0</mass>
        <inertia>
          <ixx>0.0601875</ixx>
          <ixy>0</ixy>
          <ixz>0</ixz>
          <iyy>0.0601875</iyy>
          <iyz>0</iyz>
          <izz>0.120225</izz>
        </inertia>
      </inertial>

      <collision name="collision">
        <pose>0 0 0.15 0 0 0</pose>
        <geometry>
          <mesh>
            <uri>model://vrc_valve_a/meshes/vrc_valve_a.dae</uri>
          </mesh>
        </geometry>
        <surface>
          <friction>
            <ode>
              <mu>0.7</mu>
              <mu2>0.7</mu2>
            </ode>
          </friction>
        </surface>
      </collision>

      <visual name="visual">
        <pose>0 0 0.15 0 0 0</pose>
        <geometry>
          <mesh>
            <uri>model://vrc_valve_a/meshes/vrc_valve_a.dae</uri>
          </mesh>
        </geometry>
        <material>
          <script>
            <uri>model://vrc_valve_a/materials/scripts</uri>
            <uri>model://vrc_valve_a/materials/textures</uri>
          </script>
        </material>
      </visual>
    </link>

    <link name="pipe">
      <pose>0 0 0.32 0 0 0</pose>

      <inertial>
        <mass>3.0</mass>
        <inertia>
          <ixx>0.0601875</ixx>
          <ixy>0</ixy>
          <ixz>0</ixz>
          <iyy>0.0601875</iyy>
          <iyz>0</iyz>
          <izz>0.120225</izz>
        </inertia>
      </inertial>

      <collision name="collision">
        <pose>0 0 0.017 0 0 0</pose>
        <geometry>
          <cylinder>
            <radius>0.01</radius>
            <length>0.23</length>
          </cylinder>
        </geometry>
        <surface>
          <friction>
            <ode>
              <mu>0.7</mu>
              <mu2>0.7</mu2>
            </ode>
          </friction>
        </surface>
      </collision>
      <visual name="visual">
        <pose>0 0 0.017 0 0 0</pose>
        <geometry>
          <cylinder>
            <radius>0.01</radius>
            <length>0.23</length>
          </cylinder>
        </geometry>
        <material>
          <script>
            <uri>file://media/materials/scripts</uri>
            <name>Gazebo/Green</name>
          </script>
        </material>
      </visual>
    </link>

    <joint name="valve" type="revolute">
      <parent>pipe</parent>
      <child>wheel</child>
      <axis>
        <xyz>0 0 1</xyz>
        <limit>
          <lower>-12.5663706144</lower>
          <upper>0</upper>
        </limit>
        <dynamics>
          <damping>40.0</damping>
        </dynamics>
      </axis>
      <physics>
        <ode>
          <cfm_damping>1</cfm_damping>
        </ode>
      </physics>
    </joint>

    <joint name="world_joint" type="revolute">
      <child>pipe</child>
      <parent>world</parent>
      <axis>
        <limit>
          <lower>0</lower>
          <upper>0</upper>
        </limit>
        <xyz>0 1 0</xyz>
        <dynamics>
          <damping>1.0</damping>
        </dynamics>
      </axis>
      <physics>
        <ode>
          <cfm_damping>1</cfm_damping>
        </ode>
      </physics>
    </joint>
  </model>
</sdf>
