<?xml version="1.0" ?>
<!-- =================================================================================== -->
<!-- |    This document was autogenerated by xacro from mkz.urdf.xacro                 | -->
<!-- |    EDITING THIS FILE BY HAND IS NOT RECOMMENDED                                 | -->
<!-- =================================================================================== -->
<robot name="mobility_base">
  <!-- Base Footprint -->
  <link name="base_footprint"/>
  <!-- Base Link -->
  <joint name="footprint" type="fixed">
    <parent link="base_footprint"/>
    <child link="base_link"/>
    <origin rpy="0 0 0" xyz="0 0 0.3313"/>
  </joint>
  <link name="base_link">
    <visual>
      <origin rpy="0 0 1.5707963267948966" xyz="0 0 -0.3323"/>
      <geometry>
        <mesh filename="/home/blanca/PRACTICAS/ws/install/ackerman_car_pkg/share/ackerman_car_pkg/lincoln_description/meshes/body.dae"/>
      </geometry>
    </visual>
  </link>
  <joint name="wheel_fl" type="continuous">
    <parent link="steer_fl"/>
    <child link="wheel_fl"/>
    <origin rpy="-1.5707963267948966 0 0" xyz="0 0 0"/>
    <axis xyz="0 0 1"/>
  </joint>
  <link name="wheel_fl">
    <visual>
      <origin rpy="0 -1.5707963267948966 0" xyz="0 0.002 0"/>
      <geometry>
        <mesh filename="/home/blanca/PRACTICAS/ws/install/ackerman_car_pkg/share/ackerman_car_pkg/lincoln_description/meshes/wheel.dae" scale="1 1 1"/>
      </geometry>
    </visual>
  </link>
  <joint name="wheel_fr" type="continuous">
    <parent link="steer_fr"/>
    <child link="wheel_fr"/>
    <origin rpy="-1.5707963267948966 0 0" xyz="0 0 0"/>
    <axis xyz="0 0 1"/>
  </joint>
  <link name="wheel_fr">
    <visual>
      <origin rpy="0 1.5707963267948966 0" xyz="0 0.002 0"/>
      <geometry>
        <mesh filename="/home/blanca/PRACTICAS/ws/install/ackerman_car_pkg/share/ackerman_car_pkg/lincoln_description/meshes/wheel.dae" scale="1 1 1"/>
      </geometry>
    </visual>
  </link>
  <joint name="wheel_rl" type="continuous">
    <parent link="base_link"/>
    <child link="wheel_rl"/>
    <origin rpy="-1.5707963267948966 0 0" xyz="0.0 0.7874 0"/>
    <axis xyz="0 0 1"/>
  </joint>
  <link name="wheel_rl">
    <visual>
      <origin rpy="0 -1.5707963267948966 0" xyz="0 0.002 0"/>
      <geometry>
        <mesh filename="/home/blanca/PRACTICAS/ws/install/ackerman_car_pkg/share/ackerman_car_pkg/lincoln_description/meshes/wheel.dae" scale="1 1 1"/>
      </geometry>
    </visual>
  </link>
  <joint name="wheel_rr" type="continuous">
    <parent link="base_link"/>
    <child link="wheel_rr"/>
    <origin rpy="-1.5707963267948966 0 0" xyz="0.0 -0.7874 0"/>
    <axis xyz="0 0 1"/>
  </joint>
  <link name="wheel_rr">
    <visual>
      <origin rpy="0 1.5707963267948966 0" xyz="0 0.002 0"/>
      <geometry>
        <mesh filename="/home/blanca/PRACTICAS/ws/install/ackerman_car_pkg/share/ackerman_car_pkg/lincoln_description/meshes/wheel.dae" scale="1 1 1"/>
      </geometry>
    </visual>
  </link>
  <link name="steer_fl">
    <inertial>
      <mass value="1"/>
      <inertia ixx="1.0" ixy="0.0" ixz="0.0" iyx="0.0" iyy="1.0" iyz="0.0" izx="0.0" izy="0.0" izz="1.0"/>
    </inertial>
  </link>
  <joint name="steer_fl" type="continuous">
    <parent link="base_link"/>
    <child link="steer_fl"/>
    <origin rpy="0 0 0" xyz="2.8448 0.7874 0"/>
    <axis xyz="0 0 1"/>
  </joint>
  <link name="steer_fr">
    <inertial>
      <mass value="1"/>
      <inertia ixx="1.0" ixy="0.0" ixz="0.0" iyx="0.0" iyy="1.0" iyz="0.0" izx="0.0" izy="0.0" izz="1.0"/>
    </inertial>
  </link>
  <joint name="steer_fr" type="continuous">
    <parent link="base_link"/>
    <child link="steer_fr"/>
    <origin rpy="0 0 0" xyz="2.8448 -0.7874 0"/>
    <axis xyz="0 0 1"/>
  </joint>
</robot>
