<?xml version="1.0"?>
<sdf version="1.5">

  <model name="f1_renault_camera">
    <pose>0 0 0.0 0 0 0</pose>

    <link name='base_link' />

    <joint name='chassis_link_joint' type='fixed'>
      <pose>0.0 0.0 0.0 0 0 0</pose>
      <parent>base_link</parent>
      <child>chassis_link</child>
    </joint>

    <link name='chassis_link'>
      <inertial>
        <pose>1e-06 0.07307 0.65096 0 -0 0</pose>
        <mass>1580</mass>
        <inertia>
          <ixx>1997.86</ixx>
          <ixy>-3e-05</ixy>
          <ixz>-1e-06</ixz>
          <iyy>442.769</iyy>
          <iyz>62.5206</iyz>
          <izz>2238.05</izz>
        </inertia>
      </inertial>
      <collision name='chassis_link_fixed_joint_lump__chassis_link_collision'>
        <pose>0 0 0.46936 0 -0 0</pose>
        <geometry>
          <mesh>
            <scale>0.001 0.001 0.001</scale>
            <uri>model://f1_renault/Renault/chasis.dae</uri>
          </mesh>
        </geometry>
        <surface>
          <contact>
            <ode />
          </contact>
          <friction>
            <ode>
              <mu>0.2</mu>
              <mu2>0.2</mu2>
            </ode>
          </friction>
        </surface>
      </collision>
      <visual name="visual">
        <pose>0 1.6 0.0 0 -0 1.57</pose>
        <geometry>
          <mesh>
            <scale>5 5 5</scale>
            <uri>model://f1_renault/Renault/chasis.dae</uri>
        </mesh>
      </geometry>
      </visual>
      <!-- <velocity_decay/> -->
      <!--  <gravity>1</gravity> -->
      <!--  <gravity>1</gravity> -->
      <!-- <velocity_decay/> -->
      <self_collide>1</self_collide>
      <!--  <gravity>1</gravity> -->
    </link>

    <!-- CAMERA -->
    <link name="camera_f1">
        <pose>0 0 0 0 0 0</pose>
        <inertial>
          <mass>2</mass>
            <inertia>
                <ixx>1.000000</ixx>
                <ixy>0.000000</ixy>
                <ixz>0.000000</ixz>
                <iyy>1.000000</iyy>
                <iyz>0.000000</iyz>
                <izz>1.000000</izz>
            </inertia>
        </inertial>
        <!-- Visual sphere to debug camera position-->
        <!--<visual name='visual'>
            <pose>0 2.7 0.2 0 0 0</pose>
            <geometry>
                <sphere>
                    <radius>.1</radius>
                </sphere>
            </geometry>
        </visual> -->
        <velocity_decay>
          <linear>0.000000</linear>
          <angular>0.000000</angular>
        </velocity_decay>
        <self_collide>0</self_collide>
        <kinematic>0</kinematic>
        <gravity>1</gravity>

        <sensor name='cam_f1' type='camera'>
          <pose>0 2.7 0.2 0 0 1.57</pose>
          <update_rate>20.000000</update_rate>
          <camera name='cam'>
            <horizontal_fov>1.570000</horizontal_fov>
            <image>
              <width>640</width>
              <height>480</height>
              <format>R8G8B8</format>
            </image>
            <clip>
              <near>0.100000</near>
              <far>15.000000</far>
            </clip>
          </camera>
          <plugin name="camera_controller" filename="libgazebo_ros_camera.so">
            <alwaysOn>true</alwaysOn>
            <updateRate>0.0</updateRate>
            <cameraName>camera</cameraName>
            <imageTopicName>image_raw</imageTopicName>
            <cameraInfoTopicName>camera_info</cameraInfoTopicName>
            <frameName>camera_f1</frameName>
            <hackBaseline>0.07</hackBaseline>
            <distortionK1>0.0</distortionK1>
            <distortionK2>0.0</distortionK2>
            <distortionK3>0.0</distortionK3>
            <distortionT1>0.0</distortionT1>
            <distortionT2>0.0</distortionT2>
            <ros>
                <namespace>f1ros2</namespace>
            </ros>
          </plugin>
        </sensor>

    </link>

    <joint type="fixed" name="camera_f1_joint">
        <pose>0 2.7 0.2 0 0 1.57</pose>
        <child>camera_f1</child>
        <parent>chassis_link</parent>
    </joint>

    <!-- THIRD PERSON CAMERA -->
    <link name="camera_float">
        <pose>0 0 0 0 0 0</pose>
        <inertial>
          <mass>2</mass>
            <inertia>
                <ixx>1.000000</ixx>
                <ixy>0.000000</ixy>
                <ixz>0.000000</ixz>
                <iyy>1.000000</iyy>
                <iyz>0.000000</iyz>
                <izz>1.000000</izz>
            </inertia>
        </inertial>
        <!-- Visual sphere to debug camera position-->
        <!-- <visual name='visual'>
            <pose>0 -3 2 0 0.1 1.57</pose>
            <geometry>
                <sphere>
                    <radius>.1</radius>
                </sphere>
            </geometry>
        </visual>-->
        <velocity_decay>
          <linear>0.000000</linear>
          <angular>0.000000</angular>
        </velocity_decay>
        <self_collide>0</self_collide>
        <kinematic>0</kinematic>
        <gravity>1</gravity>

        <sensor name='cam_float' type='camera'>
          <pose>0 -3 2 0 0.1 1.57</pose>
          <update_rate>20.000000</update_rate>
          <camera name='cam'>
            <horizontal_fov>1.570000</horizontal_fov>
            <image>
              <width>640</width>
              <height>480</height>
              <format>R8G8B8</format>
            </image>
            <clip>
              <near>0.100000</near>
              <far>15.000000</far>
            </clip>
          </camera>
          <plugin name="floating_camera_controller" filename="libgazebo_ros_camera.so">
            <alwaysOn>true</alwaysOn>
            <updateRate>0.0</updateRate>
            <cameraName>floating_camera</cameraName>
            <imageTopicName>image_raw</imageTopicName>
            <cameraInfoTopicName>camera_info</cameraInfoTopicName>
            <frameName>camera_float</frameName>
            <hackBaseline>0.07</hackBaseline>
            <distortionK1>0.0</distortionK1>
            <distortionK2>0.0</distortionK2>
            <distortionK3>0.0</distortionK3>
            <distortionT1>0.0</distortionT1>
            <distortionT2>0.0</distortionT2>
            <ros>
                <namespace>f1ros2</namespace>
            </ros>
          </plugin>
        </sensor>

    </link>

    <joint type="fixed" name="camera_float_joint">
        <pose>0 -3 2 0 0.1 1.57</pose>
        <child>camera_float</child>
        <parent>chassis_link</parent>
    </joint>

    <!-- BACK LEFT WHEEL -->
    <joint name='bl_axle' type='revolute'>
      <pose relative_to='chassis_link'>-0.775 -1.47364 0.304997 0 -0 0</pose>
      <parent>chassis_link</parent>
      <child>bl_1</child>
      <axis>
        <xyz>-1 0 0</xyz>
        <dynamics>
          <friction>12.031606150200002</friction>
        </dynamics>
      </axis>
    </joint>

    <link name='bl_1'>
      <pose relative_to='bl_axle'>0 0 0 0 -0 0</pose>
      <inertial>
        <pose>-0.0377 0 -0 0 -0 0</pose>
        <mass>24.5</mass>
        <inertia>
          <ixx>1.84514</ixx>
          <ixy>0</ixy>
          <ixz>0</ixz>
          <iyy>1.04961</iyy>
          <iyz>0</iyz>
          <izz>1.04961</izz>
        </inertia>
      </inertial>
      <collision name='bl_1_collision'>
        <pose relative_to='bl_axle'>0 0 0 0 1.5708 0</pose>
        <geometry>
          <cylinder>
            <radius>.3425</radius>
            <length>.22</length>
          </cylinder>
        </geometry>
        <surface>
          <contact>
            <ode />
          </contact>
          <friction>
            <ode>
              <mu>1.7</mu>
              <mu2>1.7</mu2>
            </ode>
          </friction>
        </surface>
      </collision>
      <visual name='bl_1_visual'>
        <pose>0.875 1.01364 0.1444 0 -0 0</pose>
        <geometry>
          <mesh>
            <scale>0.1 0.1 0.1</scale>
            <uri>model://f1_renault/Renault/back_left.dae</uri>
          </mesh>
        </geometry>
      </visual>
      <!--  <gravity>1</gravity> -->
      <!-- <velocity_decay/> -->
      <self_collide>1</self_collide>
    </link>

    <!-- BACK RIGHT WHEEL -->
    <joint name='br_axle' type='revolute'>
      <pose relative_to='chassis_link'>0.775 -1.45364 0.304997 0 -0 0</pose>
      <parent>chassis_link</parent>
      <child>br_1</child>
      <axis>
        <xyz>-1 0 0</xyz>
        <dynamics>
          <friction>12.031606150200002</friction>
        </dynamics>
      </axis>
    </joint>

    <link name='br_1'>
      <pose relative_to='br_axle'>0 0 0 0 -0 0</pose>
      <inertial>
        <pose>-0.0377 0 -0 0 -0 0</pose>
        <mass>24.5</mass>
        <inertia>
          <ixx>1.84514</ixx>
          <ixy>0</ixy>
          <ixz>0</ixz>
          <iyy>1.04961</iyy>
          <iyz>0</iyz>
          <izz>1.04961</izz>
        </inertia>
      </inertial>
      <collision name='br_1_collision'>
        <pose relative_to='br_axle'>0 0 0 0 1.5708 0</pose>
        <geometry>
          <cylinder>
            <radius>.3425</radius>
            <length>.22</length>
          </cylinder>
        </geometry>
        <surface>
          <contact>
            <ode />
          </contact>
          <friction>
            <ode>
              <mu>1.7</mu>
              <mu2>1.7</mu2>
            </ode>
          </friction>
        </surface>
      </collision>
      <visual name='br_1_visual'>
        <pose>-0.875 1.01364 0.1444 0 -0 0</pose>
        <geometry>
          <mesh>
            <scale>0.1 0.1 0.1</scale>
            <uri>model://f1_renault/Renault/back_right.dae</uri>
          </mesh>
        </geometry>
      </visual>
      <!--  <gravity>1</gravity> -->
      <!-- <velocity_decay/> -->
      <self_collide>1</self_collide>
    </link>

    <!-- FRONT LEFT WHEEL -->
    <joint name='l_steer' type='revolute'>
      <pose relative_to='chassis_link'>-0.7 1.61736 0.324997 0 -0 0</pose>
      <parent>chassis_link</parent>
      <child>l_steer_1</child>
      <axis>
        <xyz>0 0 1</xyz>
        <limit>
          <lower>-0.95</lower>
          <upper>0.95</upper>
        </limit>
        <dynamics>
          <friction>18.0474092253</friction>
        </dynamics>
      </axis>
    </joint>

    <link name='l_steer_1'>
      <pose relative_to='l_steer'>0 0 0 0 -0 0</pose>
      <inertial>
        <pose>0.003381 0 0.02162 0 -0 0</pose>
        <mass>1</mass>
        <inertia>
          <ixx>1</ixx>
          <ixy>0</ixy>
          <ixz>0</ixz>
          <iyy>1</iyy>
          <iyz>0</iyz>
          <izz>1</izz>
        </inertia>
      </inertial>
      <!--  <gravity>1</gravity> -->
      <!-- <velocity_decay/> -->
      <self_collide>1</self_collide>
    </link>

    <joint name='fl_axle' type='revolute'>
      <pose relative_to='l_steer_1'>-0.05 0 0 0 -0 0</pose>
      <parent>l_steer_1</parent>
      <child>fl_1</child>
      <axis>
        <xyz>-1 0 0</xyz>
        <dynamics>
          <friction>12.031606150200002</friction>
        </dynamics>
      </axis>
    </joint>

    <link name='fl_1'>
      <pose relative_to='fl_axle'>0 0 0 0 -0 0</pose>
      <inertial>
        <pose>-0.0377 0 -0 0 -0 0</pose>
        <mass>24.5</mass>
        <inertia>
          <ixx>1.84514</ixx>
          <ixy>0</ixy>
          <ixz>0</ixz>
          <iyy>1.04961</iyy>
          <iyz>0</iyz>
          <izz>1.04961</izz>
        </inertia>
      </inertial>
      <collision name='fl_1_collision'>
        <pose>0.875 -1.5174 0.1444 0 -0 0</pose>
        <geometry>
          <mesh>
            <scale>0.001 0.001 0.001</scale>
            <uri>model://autocar/meshes/fl_1.stl</uri>
          </mesh>
        </geometry>
        <surface>
          <contact>
            <ode />
          </contact>
          <friction>
            <ode>
              <mu>1.1</mu>
              <mu2>1.1</mu2>
            </ode>
          </friction>
        </surface>
      </collision>
      <visual name='fl_1_visual'>
        <pose>0.875 -1.5174 0.1444 0 -0 0</pose>
        <geometry>
          <mesh>
            <scale>0.1 0.1 0.1</scale>
            <uri>model://f1_renault/Renault/front_left.dae</uri>
          </mesh>
        </geometry>
      </visual>
      <!--  <gravity>1</gravity> -->
      <!-- <velocity_decay/> -->
      <self_collide>1</self_collide>
    </link>

    <!-- FRONT RIGHT WHEEL -->
    <joint name='r_steer' type='revolute'>
      <pose relative_to='chassis_link'>0.705 1.61736 0.324997 0 -0 0</pose>
      <parent>chassis_link</parent>
      <child>r_steer_1</child>
      <axis>
        <xyz>0 0 1</xyz>
        <limit>
          <lower>-0.95</lower>
          <upper>0.95</upper>
        </limit>
        <dynamics>
          <damping>0.01</damping>
          <friction>18.0474092253</friction>
        </dynamics>
      </axis>
    </joint>

    <link name='r_steer_1'>
      <pose relative_to='r_steer'>0 0 0 0 -0 0</pose>
      <inertial>
        <pose>0.003381 0 0.02162 0 -0 0</pose>
        <mass>1</mass>
        <inertia>
          <ixx>1</ixx>
          <ixy>0</ixy>
          <ixz>0</ixz>
          <iyy>1</iyy>
          <iyz>0</iyz>
          <izz>1</izz>
        </inertia>
      </inertial>
      <!--  <gravity>1</gravity> -->
      <!-- <velocity_decay/> -->
      <self_collide>1</self_collide>
    </link>

    <joint name='fr_axle' type='revolute'>
      <pose relative_to='r_steer_1'>0.05 0 0 0 -0 0</pose>
      <parent>r_steer_1</parent>
      <child>fr_1</child>
      <axis>
        <xyz>-1 0 0</xyz>
        <dynamics>
          <friction>12.031606150200002</friction>
        </dynamics>
      </axis>
    </joint>
    <link name='fr_1'>
      <pose relative_to='fr_axle'>0 0 0 0 -0 0</pose>
      <inertial>
        <pose>-0.0377 0 -0 0 -0 0</pose>
        <mass>24.5</mass>
        <inertia>
          <ixx>1.84514</ixx>
          <ixy>0</ixy>
          <ixz>0</ixz>
          <iyy>1.04961</iyy>
          <iyz>0</iyz>
          <izz>1.04961</izz>
        </inertia>
      </inertial>
      <collision name='fr_1_collision'>
        <pose>-0.875 -1.5174 0.1444 0 -0 0</pose>
        <geometry>
          <mesh>
            <scale>0.001 0.001 0.001</scale>
            <uri>model://autocar/meshes/fr_1.stl</uri>
          </mesh>
        </geometry>
        <surface>
          <contact>
            <ode />
          </contact>
          <friction>
            <ode>
              <mu>1.7</mu>
              <mu2>1.7</mu2>
            </ode>
          </friction>
        </surface>
      </collision>
      <visual name='fr_1_visual'>
        <pose>-0.875 -1.5174 0.1444 0 -0 0</pose>
        <geometry>
          <mesh>
            <scale>0.1 0.1 0.1</scale>
            <uri>model://f1_renault/Renault/front_right.dae</uri>
          </mesh>
        </geometry>
      </visual>
      <!--  <gravity>1</gravity> -->
      <!-- <velocity_decay/> -->
      <self_collide>1</self_collide>
    </link>

    <!-- STEERING WHEEL -->
    <link name="steering_wheel" />

    <joint name="steering_joint" type="revolute">
      <pose>-0.002 0 0 0 0 0</pose>
      <parent>chassis_link</parent>
      <child>steering_wheel</child>
      <axis>
        <xyz>-0.964118 0.000768 0.265556</xyz>
        <limit>
          <lower>-100</lower>
          <upper>100</upper>
        </limit>
        <dynamics>
          <damping>1.0</damping>
        </dynamics>
        <use_parent_model_frame>true</use_parent_model_frame>
      </axis>
      <physics>
        <ode>
          <cfm_damping>1</cfm_damping>
        </ode>
      </physics>
    </joint>

    <plugin name='ackermann_drive' filename='libgazebo_ros_ackermann_drive.so'>

      <ros>
        <namespace>f1ros2</namespace>
        <remapping>cmd_vel:=cmd_vel</remapping>
        <remapping>odom:=odom</remapping>
        <remapping>distance:=distance</remapping>
      </ros>

      <update_rate>100.0</update_rate>

      <!-- wheels -->
      <front_left_joint>fl_axle</front_left_joint>
      <front_right_joint>fr_axle</front_right_joint>
      <rear_left_joint>bl_axle</rear_left_joint>
      <rear_right_joint>br_axle</rear_right_joint>
      <left_steering_joint>l_steer</left_steering_joint>
      <right_steering_joint>r_steer</right_steering_joint>
      <steering_wheel_joint>steering_joint</steering_wheel_joint>


      <!-- Max absolute steer angle for tyre in radians-->
      <!-- Any cmd_vel angular z greater than this would be capped -->
      <max_steer>0.85</max_steer>

      <!-- Max absolute steering angle of steering wheel -->
      <!-- Max absolute steering angle of steering wheel -->
      <max_steering_angle>7.85</max_steering_angle>

      <!-- Max absolute linear speed in m/s -->
      <max_speed>20</max_speed>

      <!-- PID tuning -->
      <left_steering_pid_gain>4000 0 1</left_steering_pid_gain>
      <left_steering_i_range>0 0</left_steering_i_range>
      <right_steering_pid_gain>4000 0 1</right_steering_pid_gain>
      <right_steering_i_range>0 0</right_steering_i_range>
      <linear_velocity_pid_gain>4000 0 1</linear_velocity_pid_gain>
      <linear_velocity_i_range>0 0</linear_velocity_i_range>

      <!-- output -->
      <publish_odom>true</publish_odom>
      <publish_odom_tf>true</publish_odom_tf>
      <publish_wheel_tf>true</publish_wheel_tf>
      <publish_distance>true</publish_distance>

      <odometry_frame>odom</odometry_frame>
      <robot_base_frame>base_link</robot_base_frame>

    </plugin>

  </model>

</sdf>