<?xml version="1.0" ?>
<sdf version="1.4">
  <model name="amazon_robot2">

    <link name="base">
      <inertial>
        <pose>0 0 .05 0 0 0</pose>
        <inertia>
          <ixx>0.000</ixx>
          <ixy>0.000</ixy>
          <ixz>0.000</ixz>
          <iyy>0.000</iyy>
          <iyz>0.000</iyz>
          <izz>0.000</izz>
        </inertia>
        <mass>2</mass>
      </inertial>

      <collision name="base_collision">
        <pose>0 0 .05 0 0 0</pose>
        <geometry>
          <box>
            <size>1 .750 .15</size>
          </box>
        </geometry>
      </collision>

      <visual name="base_visual">
        <pose>0 0 .05 0 0 0</pose>
        <geometry>
          <box>
            <size>1 .750 .15</size>
          </box>
        </geometry>
        <material>
          <ambient>1 0.5 0 1</ambient>
          <diffuse>1 0.5 0 1</diffuse>
          <specular>0.1 0.1 0.1 1</specular>
          <emissive>0 0 0 0</emissive>
        </material>
      </visual>


      <collision name="front_caster_collision">
        <pose>0.40 0 -0.05 0 0 0</pose>
        <geometry>
          <sphere>
            <radius>.05</radius>
          </sphere>
        </geometry>
        <surface>
          <friction>
            <ode>
              <mu>100000.0</mu>
              <mu2>100000.0</mu2>
              <fdir1>0 0 0</fdir1>
              <slip1>0</slip1>
              <slip2>0</slip2>
            </ode>
          </friction>
        </surface>
      </collision>

      <visual name="front_caster_visual">
        <pose>0.40 0 -0.05 0 0 0</pose>
        <geometry>
          <sphere>
            <radius>.05</radius>
          </sphere>
        </geometry>
      </visual>


      <collision name="back_caster_collision">
        <pose>-0.40 0 -0.05 0 0 0</pose>
        <geometry>
          <sphere>
            <radius>.05</radius>
          </sphere>
        </geometry>
        <surface>
          <friction>
            <ode>
              <mu>100000.0</mu>
              <mu2>100000.0</mu2>
              <fdir1>0 0 0</fdir1>
              <slip1>0</slip1>
              <slip2>0</slip2>
            </ode>
          </friction>
        </surface>
      </collision>

      <visual name="back_caster_visual">
        <pose>-0.40 0 -0.05 0 0 0</pose>
        <geometry>
          <sphere>
            <radius>.05</radius>
          </sphere>
        </geometry>
      </visual>
    </link>

    <link name="left_wheel">
      <pose>0 0.30 0.05 0 1.5707 1.5707</pose>
      <collision name="collision">
        <geometry>
          <cylinder>
            <radius>.15</radius>
            <length>.05</length>
          </cylinder>
        </geometry>
      </collision>
      <visual name="visual">
        <geometry>
          <cylinder>
            <radius>.15</radius>
            <length>.05</length>
          </cylinder>
        </geometry>
      </visual>
    </link>

    <link name="right_wheel">
      <pose>0 -0.30 0.05 0 1.5707 1.5707</pose>
      <collision name="collision">
        <geometry>
          <cylinder>
            <radius>.15</radius>
            <length>.05</length>
          </cylinder>
        </geometry>
      </collision>
      <visual name="visual">
        <geometry>
          <cylinder>
            <radius>.15</radius>
            <length>.05</length>
          </cylinder>
        </geometry>
      </visual>
    </link>


    <link name="lidar">
      <inertial>
        <pose>-0.052 0 0.111 0 0 0</pose>
        <inertia>
          <ixx>0.001</ixx>
          <ixy>0.000</ixy>
          <ixz>0.000</ixz>
          <iyy>0.001</iyy>
          <iyz>0.000</iyz>
          <izz>0.001</izz>
        </inertia>
        <mass>0.125</mass>
      </inertial>

      <collision name="lidar_sensor_collision">
        <pose>-0.052 0 0.111 0 0 0</pose>
        <geometry>
          <cylinder>
            <radius>0.0508</radius>
            <length>0.055</length>
          </cylinder>
        </geometry>
      </collision>

      <visual name="lidar_sensor_visual">
        <pose>-0.064 0 0.121 0 0 0</pose>
        <geometry>
          <mesh>
            <uri>model://amazon_robot/meshes/lds.dae</uri>
            <scale>0.001 0.001 0.001</scale>
          </mesh>
        </geometry>
      </visual>

      <sensor name="hls_lfcd_lds" type="ray">
        <always_on>1</always_on>
        <visualize>0</visualize>
        <pose>-0.064 0 0.121 0 0 0</pose>
        <update_rate>1800</update_rate>
        <ray>
          <scan>
            <horizontal>
              <samples>360</samples>
              <resolution>1.000000</resolution>
              <min_angle>0.000000</min_angle>
              <max_angle>6.280000</max_angle>
            </horizontal>
          </scan>
          <range>
            <min>0.120000</min>
            <max>3.5</max>
            <resolution>0.015000</resolution>
          </range>
          <noise>
            <type>gaussian</type>
            <mean>0.0</mean>
            <stddev>0.01</stddev>
          </noise>
        </ray>
      </sensor>
    </link>

    <!-- Hokuyo laser -->
<!--    <link name="laser">-->
<!--      <pose>0.139000 0.000000 0.15 0.000000 0.000000 0.000000</pose>-->
<!--      <gravity>0</gravity>-->
<!--      <inertial>-->
<!--        <mass>0.100000</mass>-->
<!--        <inertia>-->
<!--          <ixx>1.000000</ixx>-->
<!--          <ixy>0.000000</ixy>-->
<!--          <ixz>0.000000</ixz>-->
<!--          <iyy>1.000000</iyy>-->
<!--          <iyz>0.000000</iyz>-->
<!--          <izz>1.000000</izz>-->
<!--        </inertia>-->
<!--      </inertial>-->
<!--      <visual name="visual">-->
<!--        <geometry>-->
<!--          <mesh>-->
<!--            <uri>model://hokuyo/meshes/hokuyo.dae</uri>-->
<!--          </mesh>-->
<!--        </geometry>-->
<!--      </visual>-->

<!--      <collision name="collision-base">-->
<!--        <pose>0.000000 0.000000 -0.014500 0.000000 0.000000 0.000000</pose>-->
<!--        <geometry>-->
<!--          <box>-->
<!--            <size>0.050000 0.050000 0.041000</size>-->
<!--          </box>-->
<!--        </geometry>-->
<!--        <max_contacts>10</max_contacts>-->
<!--      </collision>-->
<!--      <collision name="collision-top">-->
<!--        <pose>0.000000 0.000000 0.020500 0.000000 0.000000 0.000000</pose>-->
<!--        <geometry>-->
<!--          <cylinder>-->
<!--            <radius>0.021000</radius>-->
<!--            <length>0.029000</length>-->
<!--          </cylinder>-->
<!--        </geometry>-->
<!--        <max_contacts>10</max_contacts>-->
<!--      </collision>-->

<!--      -->
<!--      <sensor name="laser" type="ray">-->
<!--        <ray>-->
<!--          <scan>-->
<!--            <horizontal>-->
<!--              <samples>180</samples>-->
<!--              <resolution>1.000000</resolution>-->
<!--              <min_angle>-1.570000</min_angle>-->
<!--              <max_angle>1.570000</max_angle>-->
<!--            </horizontal>-->
<!--          </scan>-->
<!--          <range>-->
<!--            <min>0.080000</min>-->
<!--            <max>10.000000</max>-->
<!--            <resolution>0.010000</resolution>-->
<!--          </range>-->
<!--        </ray>-->
<!--        <update_rate>20.000000</update_rate>-->
<!--        <always_on>1</always_on>-->
<!--        <visualize>1</visualize>-->

<!--        &lt;!&ndash; ROS Laser Plugin &ndash;&gt;-->
<!--        <plugin name="gazebo_ros_head_hokuyo_controller" filename="libgazebo_ros_laser.so">-->
<!--          <topicName>laser/scan</topicName>-->
<!--          <frameName>hokuyo_link</frameName>-->
<!--          <robotNamespace></robotNamespace>-->
<!--        </plugin>-->
<!--      </sensor>-->

<!--      <velocity_decay>-->
<!--        <linear>0.000000</linear>-->
<!--        <angular>0.000000</angular>-->
<!--      </velocity_decay>-->
<!--      <self_collide>0</self_collide>-->
<!--      <kinematic>0</kinematic>-->
<!--    </link>-->

    <!-- Lift platform -->
<!--    <link name="top_lift">-->
<!--      <pose>0 0 0.2 0 0 0</pose>-->
<!--      <collision name="collision">-->
<!--        <geometry>-->
<!--          <cylinder>-->
<!--            <radius>.3375</radius>-->
<!--            <length>.03</length>-->
<!--          </cylinder>-->
<!--        </geometry>-->
<!--        <surface>-->
<!--          <friction>-->
<!--            <ode>-->
<!--              <mu>Inf</mu>-->
<!--              <mu2>Inf</mu2>-->
<!--              <slip1>0.0</slip1>-->
<!--              <slip2>0.0</slip2>-->
<!--              &lt;!&ndash;<implicit_spring_damper>1</implicit_spring_damper>-->
<!--               <maxVel>0.0</maxVel>-->
<!--               <minDepth>0.001</minDepth>&ndash;&gt;-->
<!--            </ode>-->
<!--          </friction>-->
<!--        </surface>-->
<!--      </collision>-->
<!--      <visual name="visual">-->
<!--        <geometry>-->
<!--          <cylinder>-->
<!--            <radius>.3375</radius>-->
<!--            <length>.03</length>-->
<!--          </cylinder>-->
<!--        </geometry>-->
<!--      </visual>-->
<!--    </link>-->

    <!--
    <joint type="screw" name="top_joint_lift_hinge">
      <pose>0 0 0.2 0 0 0</pose>
      <child>top_lift</child>
      <parent>base</parent>
      <axis>
        <xyz>0 0 -1</xyz>
        <limit>
          <upper>1</upper>
          <lower>0</lower>
        </limit>
      </axis>
      <thread_pitch>31.416</thread_pitch>
    </joint>
    -->

    <!-- Prismatic joint -->
<!--    <joint type="prismatic" name="top_joint_lift_hinge">-->
<!--      <pose>0 0 0.2 0 0 0</pose>-->
<!--      <child>top_lift</child>-->
<!--      <parent>base</parent>-->
<!--      <axis>-->
<!--        <xyz>0 1 0</xyz>-->
<!--        <limit>-->
<!--          <upper>0.05</upper>-->
<!--          <lower>0</lower>-->
<!--        </limit>-->
<!--      </axis>-->
<!--    </joint>-->
    <!-- Screw rotate ends here -->

    <joint type="revolute" name="left_wheel_joint">
      <pose>0 0 -0.03 0 0 0</pose>
      <child>left_wheel</child>
      <parent>base</parent>
      <axis>
        <xyz>0 0 1</xyz>
      </axis>
    </joint>

    <joint type="revolute" name="right_wheel_joint">
      <pose>0 0 0.03 0 0 0</pose>
      <child>right_wheel</child>
      <parent>base</parent>
      <axis>
        <xyz>0 0 1</xyz>
      </axis>
    </joint>

<!--    <joint name="joint_laser" type="fixed">-->
<!--      <parent>base</parent>-->
<!--      <child>laser</child>-->
<!--      <axis>-->
<!--        <xyz>0.000000 0.000000 0.000000</xyz>-->
<!--        <limit>-->
<!--          <lower>0.000000</lower>-->
<!--          <upper>0.000000</upper>-->
<!--        </limit>-->
<!--      </axis>-->
<!--    </joint>-->

    <joint name="lidar_joint" type="fixed">
      <parent>base</parent>
      <child>lidar</child>
      <pose>-0.064 0 0.121 0 0 0</pose>
      <axis>
        <xyz>0 0 1</xyz>
        <use_parent_model_frame>true</use_parent_model_frame>
      </axis>
    </joint>
    <!-- Attach the screw plugin to this model-->
<!--    <plugin name="prismatic_joint_control" filename="libgazebo_ros_screw_plugin.so">-->
<!--      <jointForce>0</jointForce>-->
<!--    </plugin>-->

    <!-- Attach the ROS Differential Drive Plugin to this model> -->
<!--    <plugin name="differential_drive_controller" filename="libgazebo_ros_diff_drive.so">-->
<!--      <alwaysOn>true</alwaysOn>-->
<!--      <updateRate>10</updateRate>-->
<!--      <legacyMode>false</legacyMode>-->
<!--      <leftJoint>left_wheel_joint</leftJoint>-->
<!--      <rightJoint>right_wheel_joint</rightJoint>-->
<!--      <wheelSeparation>0.5380</wheelSeparation>-->
<!--      <wheelDiameter>0.2410</wheelDiameter>-->
<!--      <torque>20</torque>-->
<!--      <commandTopic>cmd_vel</commandTopic>-->
<!--      <odometryTopic>odom</odometryTopic>-->
<!--      <odometryFrame>odom</odometryFrame>-->
<!--      <robotBaseFrame>base</robotBaseFrame>-->
<!--      <publishWheelTF>false</publishWheelTF>-->
<!--      <publishWheelJointState>false</publishWheelJointState>-->
<!--      <rosDebugLevel>na</rosDebugLevel>-->
<!--      <wheelAcceleration>0</wheelAcceleration>-->
<!--      <wheelTorque>5</wheelTorque>-->
<!--      <odometrySource>world</odometrySource>-->
<!--      <publishTf>1</publishTf>-->
<!--    </plugin>-->

  </model>
</sdf>
