<?xml version="1.0"?>
<sdf version="1.5">
  <model name='prius_autoparking_1laser'>

    <link name='base_link'>
      <inertial>
        <pose>0 0 0 0 -0 0</pose>
        <mass>1</mass>
        <inertia>
          <ixx>0.001</ixx>
          <ixy>0</ixy>
          <ixz>0</ixz>
          <iyy>0.001</iyy>
          <iyz>0</iyz>
          <izz>0.001</izz>
        </inertia>
      </inertial>
    </link>
    <joint name='base_link_connection' type='revolute'>
      <pose relative_to='base_link'>1.45 0 0 0 -0 1.57</pose>
      <parent>base_link</parent>
      <child>chassis</child>
      <axis>
        <limit>
          <lower>0</lower>
          <upper>0</upper>
        </limit>
        <dynamics>
          <damping>0</damping>
          <friction>0</friction>
          <spring_reference>0</spring_reference>
          <spring_stiffness>0</spring_stiffness>
        </dynamics>
        <xyz>0 0 1</xyz>
      </axis>
      <physics>
        <ode>
          <limit>
            <cfm>0</cfm>
            <erp>0.2</erp>
          </limit>
        </ode>
      </physics>
    </joint>

  <!-- LIDAR -->
    <joint name="lidar_joint" type="fixed">
      <parent>base_link</parent>
      <child>lidar_link</child>
      <pose>1 0 1.3 0 0 0</pose>
      <axis>
        <xyz>0 0 1</xyz>
      </axis>
    </joint>

    <link name="lidar_link">    
      <inertial>
        <pose>1 0 1.3 0 0 0</pose>
        <inertia>
          <ixx>0.001</ixx>
          <ixy>0.000</ixy>
          <ixz>0.000</ixz>
          <iyy>0.001</iyy>
          <iyz>0.000</iyz>
          <izz>0.001</izz>
        </inertia>
        <mass>0.114</mass>
      </inertial>
      <collision name="lidar_collision">
        <pose>1 0 1.3 0 0 0</pose>
        <geometry>
          <cylinder>
            <radius>0.0508</radius>
            <length>0.18</length>
          </cylinder>
        </geometry>
      </collision>
      <visual name="lidar_visual">
        <pose>1 0 1.5 0 0 0</pose>
        <geometry>
          <cylinder>
            <radius>0.0508</radius>
            <length>0.18</length>
          </cylinder>
        </geometry>
        <material>
          <ambient>0.0 0.0 0.0 1.0</ambient>
          <diffuse>0.0 0.0 0.0 1.0</diffuse>
          <specular>0.0 0.0 0.0 1.0</specular>
          <emissive>0.0 0.0 0.0 1.0</emissive>
        </material>
      </visual>
      <sensor name="lidar" type="ray">
        <pose>1 0 1.55 0 0 0</pose>
        <always_on>true</always_on>
        <visualize>true</visualize>
        <update_rate>5</update_rate>
        <ray>
          <scan>
            <horizontal>
              <samples>360</samples>
              <resolution>1.00000</resolution>
              <min_angle>0.000000</min_angle>
              <max_angle>6.280000</max_angle>
            </horizontal>
          </scan>
          <range>
            <min>0.120000</min>
            <max>30</max>
            <resolution>0.015000</resolution>
          </range>
          <noise>
            <type>gaussian</type>
            <mean>0.0</mean>
            <stddev>0.01</stddev>
          </noise>
        </ray>
        <plugin name="scan" filename="libgazebo_ros_ray_sensor.so">
          <ros>
            <namespace>lincoln</namespace>
            <remapping>~/out:=scan</remapping>
          </ros>
          <output_type>sensor_msgs/LaserScan</output_type>
          <frame_name>lidar_link</frame_name>
        </plugin>
      </sensor>
    </link>

    <link name='chassis'>
      <pose relative_to='base_link_connection'>0 0 0 0 -0 0</pose>
      <inertial>
        <pose>0 -0.002982 0.485295 0 -0 1.5708</pose>
        <mass>1375</mass>
        <inertia>
          <ixx>2595.52</ixx>
          <ixy>0.000189032</ixy>
          <ixz>-0.949708</ixz>
          <iyy>657.155</iyy>
          <iyz>3.48847e-06</iyz>
          <izz>2749.81</izz>
        </inertia>
      </inertial>
      <collision name='chassis_collision'>
        <pose>0 0.05 0.625 0 -0 0</pose>
        <geometry>
          <box>
            <size>1.7526 2.1 0.95</size>
          </box>
        </geometry>
      </collision>
      <collision name='chassis_fixed_joint_lump__front_bumper_collision_1'>
        <pose>0 -2 0.458488 0 -0 0</pose>
        <geometry>
          <box>
            <size>1.33728 0.48 0.566691</size>
          </box>
        </geometry>
      </collision>
      <collision name='chassis_fixed_joint_lump__hood_collision_2'>
        <pose>0 -1.90084 0.676305 0.341247 -0 0</pose>
        <geometry>
          <box>
            <size>1.59797 0.493107 0.265468</size>
          </box>
        </geometry>
      </collision>
      <collision name='chassis_fixed_joint_lump__windshield_collision_3'>
        <pose>0 -0.875105 1.03227 0.335476 -0 0</pose>
        <geometry>
          <box>
            <size>1.16838 1.65425 0.272347</size>
          </box>
        </geometry>
      </collision>
      <collision name='chassis_fixed_joint_lump__top_front_collision_4'>
        <pose>0 0.161236 1.38604 0.13503 -0 0</pose>
        <geometry>
          <box>
            <size>1.27915 0.625988 0.171868</size>
          </box>
        </geometry>
      </collision>
      <collision name='chassis_fixed_joint_lump__top_rear_collision_5'>
        <pose>0 0.817696 1.36007 -0.068997 0 0</pose>
        <geometry>
          <box>
            <size>1.28513 0.771189 0.226557</size>
          </box>
        </geometry>
      </collision>
      <collision name='chassis_fixed_joint_lump__rear_window_collision_6'>
        <pose>0 1.64053 1.17513 -0.262017 0 0</pose>
        <geometry>
          <box>
            <size>1.26785 1.11634 0.244286</size>
          </box>
        </geometry>
      </collision>
      <collision name='chassis_fixed_joint_lump__trunk_collision_7'>
        <pose>0 1.63706 0.88818 0 -0 0</pose>
        <geometry>
          <box>
            <size>1.78806 1.13899 0.482746</size>
          </box>
        </geometry>
      </collision>
      <collision name='chassis_fixed_joint_lump__back_bumper_collision_8'>
        <pose>0 2.05445 0.57787 0 -0 0</pose>
        <geometry>
          <box>
            <size>1.78165 0.512093 0.581427</size>
          </box>
        </geometry>
      </collision>
      <visual name='chassis_visual'>
        <pose>0 0 0 0 -0 0</pose>
        <geometry>
          <mesh>
            <scale>0.01 0.01 0.01</scale>
            <uri>model://prius_autoparking_1laser/meshes/hybrid_body.obj</uri>
          </mesh>
        </geometry>
      </visual>
      
      <sensor name='back_camera_sensor' type='camera'>
        <update_rate>30</update_rate>
        <camera name='back_camera'>
          <horizontal_fov>1.39626</horizontal_fov>
          <image>
            <width>800</width>
            <height>800</height>
            <format>R8G8B8</format>
          </image>
          <clip>
            <near>0.02</near>
            <far>300</far>
          </clip>
          <noise>
            <type>gaussian</type>
            <mean>0</mean>
            <stddev>0.007</stddev>
          </noise>
        </camera>
        <plugin name='back_camera_controller' filename='libgazebo_ros_camera.so'>
          <alwaysOn>0</alwaysOn>
          <updateRate>0.0</updateRate>
          <cameraName>/prius_autoparking_1laser/back_camera</cameraName>
          <imageTopicName>image_raw</imageTopicName>
          <cameraInfoTopicName>/prius_autoparking_1laser/back_camera/camera_info</cameraInfoTopicName>
          <frameName>back_camera_link_optical</frameName>
          <hackBaseline>0.07</hackBaseline>
          <distortionK1>0.0</distortionK1>
          <distortionK2>0.0</distortionK2>
          <distortionK3>0.0</distortionK3>
          <distortionT1>0.0</distortionT1>
          <distortionT2>0.0</distortionT2>
        </plugin>
        <pose>0 1.45 1.4 0 0.05 1.5707</pose>
      </sensor>
      <sensor name='back_left_far_sonar_sensor' type='ray'>
        <ray>
          <scan>
            <horizontal>
              <samples>1</samples>
              <resolution>1</resolution>
              <min_angle>0</min_angle>
              <max_angle>0</max_angle>
            </horizontal>
            <vertical>
              <samples>1</samples>
              <min_angle>0</min_angle>
              <max_angle>0</max_angle>
            </vertical>
          </scan>
          <range>
            <min>0.2</min>
            <max>5</max>
            <resolution>0.1</resolution>
          </range>
        </ray>
        <plugin name='back_left_far_sonar_sensor' filename='libgazebo_ros_range.so'>
          <topicName>/prius_autoparking_1laser/back_sonar/left_far_range</topicName>
          <frameName>back_left_far_sonar_link</frameName>
        </plugin>
        <always_on>0</always_on>
        <update_rate>5</update_rate>
        <visualize>0</visualize>
        <pose>0.7 2.4 0.5 0 -0 1.5707</pose>
      </sensor>
      <sensor name='back_left_middle_sonar_sensor' type='ray'>
        <ray>
          <scan>
            <horizontal>
              <samples>1</samples>
              <resolution>1</resolution>
              <min_angle>0</min_angle>
              <max_angle>0</max_angle>
            </horizontal>
            <vertical>
              <samples>1</samples>
              <min_angle>0</min_angle>
              <max_angle>0</max_angle>
            </vertical>
          </scan>
          <range>
            <min>0.2</min>
            <max>5</max>
            <resolution>0.1</resolution>
          </range>
        </ray>
        <plugin name='back_left_middle_sonar_sensor' filename='libgazebo_ros_range.so'>
          <topicName>/prius_autoparking_1laser/back_sonar/left_middle_range</topicName>
          <frameName>back_left_middle_sonar_link</frameName>
        </plugin>
        <always_on>0</always_on>
        <update_rate>5</update_rate>
        <visualize>0</visualize>
        <pose>0.24 2.4 0.5 0 -0 1.5707</pose>
      </sensor>
      <sensor name='back_right_far_sonar_sensor' type='ray'>
        <ray>
          <scan>
            <horizontal>
              <samples>1</samples>
              <resolution>1</resolution>
              <min_angle>0</min_angle>
              <max_angle>0</max_angle>
            </horizontal>
            <vertical>
              <samples>1</samples>
              <min_angle>0</min_angle>
              <max_angle>0</max_angle>
            </vertical>
          </scan>
          <range>
            <min>0.2</min>
            <max>5</max>
            <resolution>0.1</resolution>
          </range>
        </ray>
        <plugin name='back_right_far_sonar_sensor' filename='libgazebo_ros_range.so'>
          <topicName>/prius_autoparking_1laser/back_sonar/right_far_range</topicName>
          <frameName>back_right_far_sonar_link</frameName>
        </plugin>
        <always_on>0</always_on>
        <update_rate>5</update_rate>
        <visualize>0</visualize>
        <pose>-0.7 2.4 0.5 0 -0 1.5707</pose>
      </sensor>
      <sensor name='back_right_middle_sonar_sensor' type='ray'>
        <ray>
          <scan>
            <horizontal>
              <samples>1</samples>
              <resolution>1</resolution>
              <min_angle>0</min_angle>
              <max_angle>0</max_angle>
            </horizontal>
            <vertical>
              <samples>1</samples>
              <min_angle>0</min_angle>
              <max_angle>0</max_angle>
            </vertical>
          </scan>
          <range>
            <min>0.2</min>
            <max>5</max>
            <resolution>0.1</resolution>
          </range>
        </ray>
        <plugin name='back_right_middle_sonar_sensor' filename='libgazebo_ros_range.so'>
          <topicName>/prius_autoparking_1laser/back_sonar/right_middle_range</topicName>
          <frameName>back_right_middle_sonar_link</frameName>
        </plugin>
        <always_on>0</always_on>
        <update_rate>5</update_rate>
        <visualize>0</visualize>
        <pose>-0.24 2.4 0.5 0 -0 1.5707</pose>
      </sensor>
      
      <sensor name='front_camera_sensor' type='camera'>
        <update_rate>30</update_rate>
        <camera name='front_camera'>
          <horizontal_fov>1.39626</horizontal_fov>
          <image>
            <width>800</width>
            <height>800</height>
            <format>R8G8B8</format>
          </image>
          <clip>
            <near>0.02</near>
            <far>300</far>
          </clip>
          <noise>
            <type>gaussian</type>
            <mean>0</mean>
            <stddev>0.007</stddev>
          </noise>
        </camera>
        <plugin name='front_camera_controller' filename='libgazebo_ros_camera.so'>
          <alwaysOn>0</alwaysOn>
          <updateRate>0.0</updateRate>
          <cameraName>/prius_autoparking_1laser/front_camera</cameraName>
          <imageTopicName>image_raw</imageTopicName>
          <cameraInfoTopicName>/prius_autoparking_1laser/front_camera/camera_info</cameraInfoTopicName>
          <frameName>front_camera_link_optical</frameName>
          <hackBaseline>0.07</hackBaseline>
          <distortionK1>0.0</distortionK1>
          <distortionK2>0.0</distortionK2>
          <distortionK3>0.0</distortionK3>
          <distortionT1>0.0</distortionT1>
          <distortionT2>0.0</distortionT2>
        </plugin>
        <pose>0 -0.4 1.4 0 0.05 -1.5707</pose>
      </sensor>
      <sensor name='front_left_far_sonar_sensor' type='ray'>
        <ray>
          <scan>
            <horizontal>
              <samples>1</samples>
              <resolution>1</resolution>
              <min_angle>0</min_angle>
              <max_angle>0</max_angle>
            </horizontal>
            <vertical>
              <samples>1</samples>
              <min_angle>0</min_angle>
              <max_angle>0</max_angle>
            </vertical>
          </scan>
          <range>
            <min>0.2</min>
            <max>5</max>
            <resolution>0.1</resolution>
          </range>
        </ray>
        <plugin name='front_left_far_sonar_sensor' filename='libgazebo_ros_range.so'>
          <topicName>/prius_autoparking_1laser/front_sonar/left_far_range</topicName>
          <frameName>front_left_far_sonar_link</frameName>
        </plugin>
        <always_on>0</always_on>
        <update_rate>5</update_rate>
        <visualize>0</visualize>
        <pose>0.7 -2.1 0.5 0 0 -1.5707</pose>
      </sensor>
      <sensor name='front_left_laser_sensor' type='ray'>
        <ray>
          <scan>
            <horizontal>
              <samples>640</samples>
              <resolution>1</resolution>
              <min_angle>-2.26889</min_angle>
              <max_angle>2.2689</max_angle>
            </horizontal>
            <vertical>
              <samples>1</samples>
              <min_angle>0</min_angle>
              <max_angle>0</max_angle>
            </vertical>
          </scan>
          <range>
            <min>0.2</min>
            <max>30</max>
            <resolution>0.01</resolution>
          </range>
        </ray>
        <plugin name='front_left_laser' filename='libgazebo_ros_laser.so'>
          <topicName>/prius_autoparking_1laser/front_left_laser/scan</topicName>
          <frameName>front_left_laser_link</frameName>
        </plugin>
        <always_on>1</always_on>
        <update_rate>30</update_rate>
        <visualize>0</visualize>
        <pose>1 -2.3 0.5 0 0.05 0</pose>
      </sensor>
      <sensor name='front_left_middle_sonar_sensor' type='ray'>
        <ray>
          <scan>
            <horizontal>
              <samples>1</samples>
              <resolution>1</resolution>
              <min_angle>0</min_angle>
              <max_angle>0</max_angle>
            </horizontal>
            <vertical>
              <samples>1</samples>
              <min_angle>0</min_angle>
              <max_angle>0</max_angle>
            </vertical>
          </scan>
          <range>
            <min>0.2</min>
            <max>5</max>
            <resolution>0.1</resolution>
          </range>
        </ray>
        <plugin name='front_left_middle_sonar_sensor' filename='libgazebo_ros_range.so'>
          <topicName>/prius_autoparking_1laser/front_sonar/left_middle_range</topicName>
          <frameName>front_left_middle_sonar_link</frameName>
        </plugin>
        <always_on>0</always_on>
        <update_rate>5</update_rate>
        <visualize>0</visualize>
        <pose>0.24 -2.3 0.5 0 0 -1.5707</pose>
      </sensor>
      <sensor name='front_right_far_sonar_sensor' type='ray'>
        <ray>
          <scan>
            <horizontal>
              <samples>1</samples>
              <resolution>1</resolution>
              <min_angle>0</min_angle>
              <max_angle>0</max_angle>
            </horizontal>
            <vertical>
              <samples>1</samples>
              <min_angle>0</min_angle>
              <max_angle>0</max_angle>
            </vertical>
          </scan>
          <range>
            <min>0.2</min>
            <max>5</max>
            <resolution>0.1</resolution>
          </range>
        </ray>
        <plugin name='front_right_far_sonar_sensor' filename='libgazebo_ros_range.so'>
          <topicName>/prius_autoparking_1laser/front_sonar/right_far_range</topicName>
          <frameName>front_right_far_sonar_link</frameName>
        </plugin>
        <always_on>0</always_on>
        <update_rate>5</update_rate>
        <visualize>0</visualize>
        <pose>-0.7 -2.1 0.5 0 0 -1.5707</pose>
      </sensor>
      <sensor name='front_right_laser_sensor' type='ray'>
        <ray>
          <scan>
            <horizontal>
              <samples>640</samples>
              <resolution>1</resolution>
              <min_angle>-2.26889</min_angle>
              <max_angle>2.2689</max_angle>
            </horizontal>
            <vertical>
              <samples>1</samples>
              <min_angle>0</min_angle>
              <max_angle>0</max_angle>
            </vertical>
          </scan>
          <range>
            <min>0.2</min>
            <max>30</max>
            <resolution>0.01</resolution>
          </range>
        </ray>
        <plugin name='front_right_laser' filename='libgazebo_ros_laser.so'>
          <topicName>/prius_autoparking_1laser/front_right_laser/scan</topicName>
          <frameName>front_right_laser_link</frameName>
        </plugin>
        <always_on>1</always_on>
        <update_rate>30</update_rate>
        <visualize>0</visualize>
        <pose>-1 -2.3 0.5 -0 0.05 3.14</pose>
      </sensor>
      <sensor name='front_right_middle_sonar_sensor' type='ray'>
        <ray>
          <scan>
            <horizontal>
              <samples>1</samples>
              <resolution>1</resolution>
              <min_angle>0</min_angle>
              <max_angle>0</max_angle>
            </horizontal>
            <vertical>
              <samples>1</samples>
              <min_angle>0</min_angle>
              <max_angle>0</max_angle>
            </vertical>
          </scan>
          <range>
            <min>0.2</min>
            <max>5</max>
            <resolution>0.1</resolution>
          </range>
        </ray>
        <plugin name='front_right_middle_sonar_sensor' filename='libgazebo_ros_range.so'>
          <topicName>/prius_autoparking_1laser/front_sonar/right_middle_range</topicName>
          <frameName>front_right_middle_sonar_link</frameName>
        </plugin>
        <always_on>0</always_on>
        <update_rate>5</update_rate>
        <visualize>0</visualize>
        <pose>-0.24 -2.3 0.5 0 0 -1.5707</pose>
      </sensor>
      <sensor name='left_camera_sensor' type='camera'>
        <update_rate>30</update_rate>
        <camera name='left_camera'>
          <horizontal_fov>1.39626</horizontal_fov>
          <image>
            <width>800</width>
            <height>800</height>
            <format>R8G8B8</format>
          </image>
          <clip>
            <near>0.02</near>
            <far>300</far>
          </clip>
          <noise>
            <type>gaussian</type>
            <mean>0</mean>
            <stddev>0.007</stddev>
          </noise>
        </camera>
        <plugin name='left_camera_controller' filename='libgazebo_ros_camera.so'>
          <alwaysOn>0</alwaysOn>
          <updateRate>0.0</updateRate>
          <cameraName>/prius_autoparking_1laser/left_camera</cameraName>
          <imageTopicName>image_raw</imageTopicName>
          <cameraInfoTopicName>/prius_autoparking_1laser/left_camera/camera_info</cameraInfoTopicName>
          <frameName>left_camera_link_optical</frameName>
          <hackBaseline>0.07</hackBaseline>
          <distortionK1>0.0</distortionK1>
          <distortionK2>0.0</distortionK2>
          <distortionK3>0.0</distortionK3>
          <distortionT1>0.0</distortionT1>
          <distortionT2>0.0</distortionT2>
        </plugin>
        <pose>1 -0.7 1 0 0.05 1</pose>
      </sensor>
      <sensor name='right_camera_sensor' type='camera'>
        <update_rate>30</update_rate>
        <camera name='right_camera'>
          <horizontal_fov>1.39626</horizontal_fov>
          <image>
            <width>800</width>
            <height>800</height>
            <format>R8G8B8</format>
          </image>
          <clip>
            <near>0.02</near>
            <far>300</far>
          </clip>
          <noise>
            <type>gaussian</type>
            <mean>0</mean>
            <stddev>0.007</stddev>
          </noise>
        </camera>
        <plugin name='right_camera_controller' filename='libgazebo_ros_camera.so'>
          <alwaysOn>0</alwaysOn>
          <updateRate>0.0</updateRate>
          <cameraName>/prius_autoparking_1laser/right_camera</cameraName>
          <imageTopicName>image_raw</imageTopicName>
          <cameraInfoTopicName>/prius_autoparking_1laser/right_camera/camera_info</cameraInfoTopicName>
          <frameName>right_camera_link_optical</frameName>
          <hackBaseline>0.07</hackBaseline>
          <distortionK1>0.0</distortionK1>
          <distortionK2>0.0</distortionK2>
          <distortionK3>0.0</distortionK3>
          <distortionT1>0.0</distortionT1>
          <distortionT2>0.0</distortionT2>
        </plugin>
        <pose>-1 -0.7 1 0 0.05 2.1416</pose>
      </sensor>
    </link>
    <joint name='front_left_steer_joint' type='revolute'>
      <pose relative_to='chassis'>0.767 -1.41 0.3 0 -0 0</pose>
      <parent>chassis</parent>
      <child>fl_axle</child>
      <axis>
        <xyz>0 0 1</xyz>
        <limit>
          <effort>1e+07</effort>
          <velocity>1e+06</velocity>
          <lower>-1e+16</lower>
          <upper>1e+16</upper>
        </limit>
        <dynamics>
          <spring_reference>0</spring_reference>
          <spring_stiffness>0</spring_stiffness>
        </dynamics>
      </axis>
    </joint>
    <link name='fl_axle'>
      <pose relative_to='front_left_steer_joint'>0 0 0 0 -0 0</pose>
      <inertial>
        <pose>0 0 0 0 -0 0</pose>
        <mass>1</mass>
        <inertia>
          <ixx>0.004</ixx>
          <ixy>0</ixy>
          <ixz>0</ixz>
          <iyy>0.004</iyy>
          <iyz>0</iyz>
          <izz>0.004</izz>
        </inertia>
      </inertial>
    </link>
    <joint name='front_left_wheel_joint' type='revolute'>
      <pose relative_to='fl_axle'>0 0 0 0 -0 0</pose>
      <parent>fl_axle</parent>
      <child>front_left_wheel</child>
      <axis>
        <xyz>1 0 0</xyz>
        <limit>
          <lower>-1e+16</lower>
          <upper>1e+16</upper>
        </limit>
        <dynamics>
          <spring_reference>0</spring_reference>
          <spring_stiffness>0</spring_stiffness>
        </dynamics>
      </axis>
    </joint>
    <link name='front_left_wheel'>
      <pose relative_to='front_left_wheel_joint'>0 0 0 0 -0 0</pose>
      <inertial>
        <pose>0 0 0 0 -0 0</pose>
        <mass>11</mass>
        <inertia>
          <ixx>0.586312</ixx>
          <ixy>0</ixy>
          <ixz>0</ixz>
          <iyy>0.335529</iyy>
          <iyz>0</iyz>
          <izz>0.335529</izz>
        </inertia>
      </inertial>
      <collision name='front_left_wheel_collision_collision'>
        <pose>0 0 0 0 -0 0</pose>
        <geometry>
          <sphere>
            <radius>0.31265</radius>
          </sphere>
        </geometry>
        <surface>
          <contact>
            <ode>
              <kp>1e+08</kp>
              <min_depth>0.005</min_depth>
            </ode>
          </contact>
          <friction>
            <ode>
              <mu>0.9</mu>
              <mu2>0.9</mu2>
            </ode>
          </friction>
        </surface>
      </collision>
      <visual name='front_left_wheel_visual'>
        <pose>0 0 0 0 -0 0</pose>
        <geometry>
          <mesh>
            <scale>0.01 0.01 0.01</scale>
            <uri>model://prius_autoparking_1laser/meshes/wheel.obj</uri>
          </mesh>
        </geometry>
      </visual>
    </link>
    <joint name='front_right_steer_joint' type='revolute'>
      <pose relative_to='chassis'>-0.767 -1.41 0.3 0 -0 0</pose>
      <parent>chassis</parent>
      <child>fr_axle</child>
      <axis>
        <xyz>0 0 1</xyz>
        <limit>
          <effort>1e+07</effort>
          <velocity>1e+06</velocity>
          <lower>-1e+16</lower>
          <upper>1e+16</upper>
        </limit>
        <dynamics>
          <spring_reference>0</spring_reference>
          <spring_stiffness>0</spring_stiffness>
        </dynamics>
      </axis>
    </joint>
    <link name='fr_axle'>
      <pose relative_to='front_right_steer_joint'>0 0 0 0 -0 0</pose>
      <inertial>
        <pose>0 0 0 0 -0 0</pose>
        <mass>1</mass>
        <inertia>
          <ixx>0.004</ixx>
          <ixy>0</ixy>
          <ixz>0</ixz>
          <iyy>0.004</iyy>
          <iyz>0</iyz>
          <izz>0.004</izz>
        </inertia>
      </inertial>
    </link>
    <joint name='front_right_wheel_joint' type='revolute'>
      <pose relative_to='fr_axle'>0 0 0 0 -0 0</pose>
      <parent>fr_axle</parent>
      <child>front_right_wheel</child>
      <axis>
        <xyz>1 0 0</xyz>
        <limit>
          <lower>-1e+16</lower>
          <upper>1e+16</upper>
        </limit>
        <dynamics>
          <spring_reference>0</spring_reference>
          <spring_stiffness>0</spring_stiffness>
        </dynamics>
      </axis>
    </joint>
    <link name='front_right_wheel'>
      <pose relative_to='front_right_wheel_joint'>0 0 0 0 -0 0</pose>
      <inertial>
        <pose>0 0 0 0 -0 0</pose>
        <mass>11</mass>
        <inertia>
          <ixx>0.586312</ixx>
          <ixy>0</ixy>
          <ixz>0</ixz>
          <iyy>0.335529</iyy>
          <iyz>0</iyz>
          <izz>0.335529</izz>
        </inertia>
      </inertial>
      <collision name='front_right_wheel_collision_collision'>
        <pose>0 0 0 0 -0 0</pose>
        <geometry>
          <sphere>
            <radius>0.31265</radius>
          </sphere>
        </geometry>
        <surface>
          <contact>
            <ode>
              <kp>1e+08</kp>
              <min_depth>0.005</min_depth>
            </ode>
          </contact>
          <friction>
            <ode>
              <mu>0.9</mu>
              <mu2>0.9</mu2>
            </ode>
          </friction>
        </surface>
      </collision>
      <visual name='front_right_wheel_visual'>
        <pose>0 0 0 0 -0 0</pose>
        <geometry>
          <mesh>
            <scale>0.01 0.01 0.01</scale>
            <uri>model://prius_autoparking_1laser/meshes/wheel.obj</uri>
          </mesh>
        </geometry>
      </visual>
    </link>
    <joint name='rear_left_wheel_joint' type='revolute'>
      <pose relative_to='chassis'>0.793 1.45 0.3 0 -0 0</pose>
      <parent>chassis</parent>
      <child>rear_left_wheel</child>
      <axis>
        <xyz>1 0 0</xyz>
        <limit>
          <lower>-1e+16</lower>
          <upper>1e+16</upper>
        </limit>
        <dynamics>
          <spring_reference>0</spring_reference>
          <spring_stiffness>0</spring_stiffness>
        </dynamics>
      </axis>
    </joint>
    <link name='rear_left_wheel'>
      <pose relative_to='rear_left_wheel_joint'>0 0 0 0 -0 0</pose>
      <inertial>
        <pose>0 0 0 0 -0 0</pose>
        <mass>11</mass>
        <inertia>
          <ixx>0.586312</ixx>
          <ixy>0</ixy>
          <ixz>0</ixz>
          <iyy>0.335529</iyy>
          <iyz>0</iyz>
          <izz>0.335529</izz>
        </inertia>
      </inertial>
      <collision name='rear_left_wheel_collision_collision'>
        <pose>0 0 0 0 -0 0</pose>
        <geometry>
          <sphere>
            <radius>0.31265</radius>
          </sphere>
        </geometry>
        <surface>
          <contact>
            <ode>
              <kp>1e+08</kp>
              <min_depth>0.005</min_depth>
            </ode>
          </contact>
          <friction>
            <ode>
              <mu>0.9</mu>
              <mu2>0.9</mu2>
            </ode>
          </friction>
        </surface>
      </collision>
      <visual name='rear_left_wheel_visual'>
        <pose>0 0 0 0 -0 0</pose>
        <geometry>
          <mesh>
            <scale>0.01 0.01 0.01</scale>
            <uri>model://prius_autoparking_1laser/meshes/wheel.obj</uri>
          </mesh>
        </geometry>
      </visual>
    </link>
    <joint name='rear_right_wheel_joint' type='revolute'>
      <pose relative_to='chassis'>-0.793 1.45 0.3 0 -0 0</pose>
      <parent>chassis</parent>
      <child>rear_right_wheel</child>
      <axis>
        <xyz>1 0 0</xyz>
        <limit>
          <lower>-1e+16</lower>
          <upper>1e+16</upper>
        </limit>
        <dynamics>
          <spring_reference>0</spring_reference>
          <spring_stiffness>0</spring_stiffness>
        </dynamics>
      </axis>
    </joint>
    <link name='rear_right_wheel'>
      <pose relative_to='rear_right_wheel_joint'>0 0 0 0 -0 0</pose>
      <inertial>
        <pose>0 0 0 0 -0 0</pose>
        <mass>11</mass>
        <inertia>
          <ixx>0.586312</ixx>
          <ixy>0</ixy>
          <ixz>0</ixz>
          <iyy>0.335529</iyy>
          <iyz>0</iyz>
          <izz>0.335529</izz>
        </inertia>
      </inertial>
      <collision name='rear_right_wheel_collision_collision'>
        <pose>0 0 0 0 -0 0</pose>
        <geometry>
          <sphere>
            <radius>0.31265</radius>
          </sphere>
        </geometry>
        <surface>
          <contact>
            <ode>
              <kp>1e+08</kp>
              <min_depth>0.005</min_depth>
            </ode>
          </contact>
          <friction>
            <ode>
              <mu>0.9</mu>
              <mu2>0.9</mu2>
            </ode>
          </friction>
        </surface>
      </collision>
      <visual name='rear_right_wheel_visual'>
        <pose>0 0 0 0 -0 0</pose>
        <geometry>
          <mesh>
            <scale>0.01 0.01 0.01</scale>
            <uri>model://prius_autoparking_1laser/meshes/wheel.obj</uri>
          </mesh>
        </geometry>
      </visual>
    </link>
    <joint name='steering_joint' type='revolute'>
      <pose relative_to='chassis'>0.357734 -0.627868 0.988243 -1.3021 0 0</pose>
      <parent>chassis</parent>
      <child>steering_wheel</child>
      <axis>
        <xyz>0 0 1</xyz>
        <limit>
          <effort>1e+07</effort>
          <velocity>1e+06</velocity>
          <lower>-1e+16</lower>
          <upper>1e+16</upper>
        </limit>
        <dynamics>
          <spring_reference>0</spring_reference>
          <spring_stiffness>0</spring_stiffness>
        </dynamics>
      </axis>
    </joint>
    <link name='steering_wheel'>
      <pose relative_to='steering_joint'>0 0 0 0 -0 0</pose>
      <inertial>
        <pose>0 0 0 0 -0 0</pose>
        <mass>1</mass>
        <inertia>
          <ixx>0.145833</ixx>
          <ixy>0</ixy>
          <ixz>0</ixz>
          <iyy>0.145833</iyy>
          <iyz>0</iyz>
          <izz>0.125</izz>
        </inertia>
      </inertial>
      <visual name='steering_wheel_visual'>
        <pose>0 0 0 1.3021 -0 0</pose>
        <geometry>
          <mesh>
            <scale>0.01 0.01 0.01</scale>
            <uri>model://prius_autoparking_1laser/meshes/steering_wheel.obj</uri>
          </mesh>
        </geometry>
      </visual>
    </link>
    <plugin name='pruis_hybrid_drive' filename='libprius_autoparking_1laserHybridPlugin.so'>
      <chassis>chassis</chassis>
      <front_left_wheel>front_left_wheel_joint</front_left_wheel>
      <front_right_wheel>front_right_wheel_joint</front_right_wheel>
      <front_left_wheel_steering>front_left_steer_joint</front_left_wheel_steering>
      <front_right_wheel_steering>front_right_steer_joint</front_right_wheel_steering>
      <back_left_wheel>rear_left_wheel_joint</back_left_wheel>
      <back_right_wheel>rear_right_wheel_joint</back_right_wheel>
      <steering_wheel>steering_joint</steering_wheel>
      <chassis_aero_force_gain>0.63045</chassis_aero_force_gain>
      <front_torque>859.4004393000001</front_torque>
      <back_torque>0</back_torque>
      <front_brake_torque>1031.28052716</front_brake_torque>
      <back_brake_torque>687.5203514400001</back_brake_torque>
      <max_speed>37.998337013956565</max_speed>
      <min_gas_flow>8.981854013171626e-05</min_gas_flow>
      <gas_efficiency>0.371</gas_efficiency>
      <battery_charge_watt_hours>291</battery_charge_watt_hours>
      <battery_discharge_watt_hours>214</battery_discharge_watt_hours>
      <max_steer>0.6458</max_steer>
      <flwheel_steering_p_gain>1e4</flwheel_steering_p_gain>
      <frwheel_steering_p_gain>1e4</frwheel_steering_p_gain>
      <flwheel_steering_i_gain>0</flwheel_steering_i_gain>
      <frwheel_steering_i_gain>0</frwheel_steering_i_gain>
      <flwheel_steering_d_gain>3e2</flwheel_steering_d_gain>
      <frwheel_steering_d_gain>3e2</frwheel_steering_d_gain>
    </plugin>
    <plugin name='joint_state_publisher' filename='libgazebo_ros_joint_state_publisher.so'>
      <jointName>rear_right_wheel_joint, rear_left_wheel_joint, front_right_wheel_joint, front_left_wheel_joint, front_right_steer_joint, front_left_steer_joint, steering_joint</jointName>
      <updateRate>100.0</updateRate>
      <alwaysOn>1</alwaysOn>
    </plugin>
    <static>0</static>
    <plugin name='p3d' filename='libgazebo_ros_p3d.so'>
      <bodyName>base_link</bodyName>
      <topicName>base_pose_ground_truth</topicName>
      <frameName>map</frameName>
      <updateRate>100.0</updateRate>
    </plugin>
    
    <plugin name="object_controller" filename="libgazebo_ros_planar_move.so">
      <commandTopic>prius/cmd_vel</commandTopic>
      <odometryTopic>prius/odom</odometryTopic>
      <odometryFrame>odom</odometryFrame>
      <odometryRate>20.0</odometryRate>
      <robotBaseFrame>prius</robotBaseFrame>
</plugin>
    
    
    
    
    
    
    
    
  </model>
</sdf>
