<?xml version='1.0'?>
<sdf version='1.4'>
  <model name="my_robot">
    <link name='my_robot'>
       <pose>0 0 .1 0 0 0</pose>

       <collision name='collision'>
         <geometry>
           <box>
             <size>.2 .5 .2</size>
           </box>
         </geometry>
       </collision>

       <visual name='visual'>
         <geometry>
           <box>
             <size>.2 .5 .2</size>
           </box>
         </geometry>
       </visual>
     </link>


     <collision name='caster_collision'>
       <pose>-0.15 0 -0.05 0 0 0</pose>
       <geometry>
           <sphere>
           <radius>.05</radius>
         </sphere>
       </geometry>

       <surface>
         <friction>
           <ode>
             <mu>0</mu>
             <mu2>0</mu2>
             <slip1>1.0</slip1>
             <slip2>1.0</slip2>
           </ode>
         </friction>
       </surface>
     </collision>

     <visual name='caster_visual'>
       <pose>-0.15 0 -0.05 0 0 0</pose>
       <geometry>
         <sphere>
           <radius>.05</radius>
         </sphere>
       </geometry>
     </visual>


     <link name="left_wheel">
       <pose>0.1 0.2 0.1 0 1.5707 1.5707</pose>
       <collision name="collision">
         <geometry>
           <cylinder>
             <radius>0.3</radius>
             <length>.1</length>
           </cylinder>
         </geometry>
       </collision>
       <visual name="visual">
         <geometry>
           <cylinder>
             <radius>0.3</radius>
             <length>.1</length>
           </cylinder>
         </geometry>
       </visual>
     </link>


     <link name="right_wheel">
       <pose>0.1 -0.2 0.1 0 1.5707 1.5707</pose>
       <collision name="collision">
         <geometry>
           <cylinder>
             <radius>0.3</radius>
             <length>.1</length>
           </cylinder>
         </geometry>
       </collision>
       <visual name="visual">
         <geometry>
           <cylinder>
             <radius>0.3</radius>
             <length>.1</length>
           </cylinder>
         </geometry>
       </visual>
     </link>

     <joint type="revolute" name="left_wheel_hinge">
       <pose>0 0 -0.03 0 0 0</pose>
       <child>left_wheel</child>
       <parent>my_robot</parent>
       <inertial>
         <mass>1</mass>
         <inertia>
           <ixx>0.00307917</ixx>
           <iyy>0.00307917</iyy>
           <izz>0.005625</izz>
           <ixy>0</ixy>
           <ixz>0</ixz>
           <iyz>0</iyz>
         </inertia>
         <pose>0 0 0 0 -0 0</pose>
      </inertial>
       <axis>
         <xyz>0 1 0</xyz>
       </axis>
     </joint>

     <joint type="revolute" name="right_wheel_hinge">
       <pose>0 0 0.03 0 0 0</pose>
       <child>right_wheel</child>
       <parent>my_robot</parent>
       <mass>1</mass>
       <inertial>
         <mass>0.5</mass>
         <inertia>
           <ixx>0.00307917</ixx>
           <iyy>0.00307917</iyy>
           <izz>0.005625</izz>
           <ixy>0</ixy>
           <ixz>0</ixz>
           <iyz>0</iyz>
         </inertia>
         <pose>0 0 0 0 -0 0</pose>
      </inertial>
       <axis>
         <xyz>0 1 0</xyz>
       </axis>
     </joint>
   </model>
   <!-- <gazebo>
     <plugin name="object_controller" filename="libgazebo_ros_planar_move.so">
        <commandTopic>cmd_vel</commandTopic>
        <odometryTopic>odom</odometryTopic>
        <odometryFrame>odom</odometryFrame>
        <odometryRate>20.0</odometryRate>
        <robotBaseFrame>my_robot</robotBaseFrame>
    </plugin>
  </gazebo> -->
</sdf>
