<?xml version="1.0" encoding="utf-8"?>
<!-- =================================================================================== -->
<!-- |    This document was autogenerated by xacro from /home/shreyas/Projects/GSoC/colab-gsoc2020-Shreyas_Gokhale/catkin_workspace/src/amazon_robot_description/urdf/amazon_warehouse_robot.urdf.xacro | -->
<!-- |    EDITING THIS FILE BY HAND IS NOT RECOMMENDED                                 | -->
<!-- |    I have edited it anyway                                                      | -->
<!-- =================================================================================== -->
<robot name="amazon_robot2">
    <!-- Init colour -->
    <material name="black">
        <color rgba="0.0 0.0 0.0 1.0"/>
    </material>
    <material name="dark">
        <color rgba="0.3 0.3 0.3 1.0"/>
    </material>
    <material name="light_black">
        <color rgba="0.4 0.4 0.4 1.0"/>
    </material>
    <material name="blue">
        <color rgba="0.0 0.0 0.8 1.0"/>
    </material>
    <material name="green">
        <color rgba="0.0 0.8 0.0 1.0"/>
    </material>
    <material name="grey">
        <color rgba="0.5 0.5 0.5 1.0"/>
    </material>
    <material name="orange">
        <color rgba="1.0 0.423529411765 0.0392156862745 1.0"/>
    </material>
    <material name="brown">
        <color rgba="0.870588235294 0.811764705882 0.764705882353 1.0"/>
    </material>
    <material name="red">
        <color rgba="0.8 0.0 0.0 1.0"/>
    </material>
    <material name="white">
        <color rgba="1.0 1.0 1.0 1.0"/>
    </material>
    <gazebo reference="base_link">
        <material>Gazebo/Orange</material>
    </gazebo>
    <gazebo reference="wheel_left_link">
        <mu1>20</mu1>
        <mu2>20</mu2>
        <kp>500000.0</kp>
        <kd>10.0</kd>
        <minDepth>0.001</minDepth>
        <maxVel>0.1</maxVel>
        <fdir1>1 0 0</fdir1>
        <material>Gazebo/FlatBlack</material>
    </gazebo>
    <gazebo reference="wheel_right_link">
        <mu1>20</mu1>
        <mu2>20</mu2>
        <kp>500000.0</kp>
        <kd>10.0</kd>
        <minDepth>0.001</minDepth>
        <maxVel>0.1</maxVel>
        <fdir1>1 0 0</fdir1>
        <material>Gazebo/FlatBlack</material>
    </gazebo>
    <gazebo reference="caster_back_right_link">
        <mu1>20</mu1>
        <mu2>20</mu2>
        <kp>1000000.0</kp>
        <kd>100.0</kd>
        <minDepth>0.001</minDepth>
        <maxVel>1.0</maxVel>
        <material>Gazebo/FlatBlack</material>
    </gazebo>
    <gazebo reference="caster_back_left_link">
        <mu1>20</mu1>
        <mu2>20</mu2>
        <kp>1000000.0</kp>
        <kd>100.0</kd>
        <minDepth>0.001</minDepth>
        <maxVel>1.0</maxVel>
        <material>Gazebo/FlatBlack</material>
    </gazebo>
    <gazebo reference="platform_joint">
        <mu1>20000</mu1>
        <mu2>20000</mu2>
        <kp>1000000.0</kp>
        <material>Gazebo/FlatBlack</material>
    </gazebo>
    <gazebo reference="lift_joint">
        <mu1>20000</mu1>
        <mu2>20000</mu2>
        <kp>1000000.0</kp>
        <material>Gazebo/Red</material>
    </gazebo>
     <gazebo reference="lift_link">
        <mu1>20000</mu1>
        <mu2>20000</mu2>
        <kp>1000000.0</kp>
        <material>Gazebo/Red</material>
    </gazebo>
    <gazebo reference="imu_link">
        <sensor name="imu" type="imu">
            <always_on>true</always_on>
            <visualize>false</visualize>
        </sensor>
        <material>Gazebo/Grey</material>
    </gazebo>
    <gazebo reference="base_scan">
        <material>Gazebo/FlatBlack</material>
        <sensor name="lds_lfcd_sensor" type="ray">
            <pose>0 0 0 0 0 0</pose>
            <visualize>false</visualize>
            <update_rate>5</update_rate>
            <ray>
                <scan>
                    <horizontal>
                        <samples>360</samples>
                        <resolution>1</resolution>
                        <min_angle>0.0</min_angle>
                        <max_angle>6.28319</max_angle>
                    </horizontal>
                </scan>
                <range>
                    <min>0.120</min>
                    <max>3.5</max>
                    <resolution>0.015</resolution>
                </range>
                <noise>
                    <type>gaussian</type>
                    <mean>0.0</mean>
                    <stddev>0.01</stddev>
                </noise>
            </ray>
        </sensor>
    </gazebo>
    <!-- ros_control plugin -->
    <link name="base_footprint"/>
    <joint name="base_joint" type="fixed">
        <parent link="base_footprint"/>
        <child link="base_link"/>
        <origin rpy="0 0 0" xyz="0 0 0.010"/>
    </joint>
    <link name="base_link">
        <visual>
            <origin rpy="0 0 0" xyz="-0.064 0 0.0"/>
            <geometry>
                <mesh filename="package://amazon_robot_description/meshes/bases/waffle_pi_base.stl" scale="0.002 0.002 0.002"/>
            </geometry>
            <material name="orange"/>
        </visual>
        <collision>
            <origin rpy="0 0 0" xyz="-0.064 0 0.047"/>
            <geometry>
                <box size="0.532 0.532 0.188"/>
            </geometry>
        </collision>
        <inertial>
            <origin rpy="0 0 0" xyz="0 0 0"/>
            <mass value="1.3729096e+00"/>
            <inertia ixx="8.7002718e-03" ixy="-4.7576583e-05" ixz="1.1160499e-04" iyy="8.6195418e-03" iyz="-3.5422299e-06" izz="1.4612727e-02"/>
        </inertial>
    </link>
    <joint name="wheel_left_joint" type="continuous">
        <parent link="base_link"/>
        <child link="wheel_left_link"/>
        <origin rpy="-1.57 0 0" xyz="0.0 0.288 0.046"/>
        <axis xyz="0 0 1"/>
    </joint>
    <link name="wheel_left_link">
        <visual>
            <origin rpy="1.57 0 0" xyz="0 0 0"/>
            <geometry>
                <mesh filename="package://amazon_robot_description/meshes/wheels/left_tire.stl" scale="0.002 0.002 0.002"/>
            </geometry>
            <material name="dark"/>
        </visual>
        <collision>
            <origin rpy="0 0 0" xyz="0 0 0"/>
            <geometry>
                <cylinder length="0.020" radius="0.072"/>
            </geometry>
        </collision>
        <inertial>
            <origin xyz="0 0 0"/>
            <mass value="2.8498940e-02"/>
            <inertia ixx="1.1175580e-05" ixy="-4.2369783e-11" ixz="-5.9381719e-09" iyy="1.1192413e-05" iyz="-1.4400107e-11" izz="2.0712558e-05"/>
        </inertial>
    </link>
    <joint name="wheel_right_joint" type="continuous">
        <parent link="base_link"/>
        <child link="wheel_right_link"/>
        <origin rpy="-1.57 0 0" xyz="0.0 -0.288 0.046"/>
        <axis xyz="0 0 1"/>
    </joint>
    <link name="wheel_right_link">
        <visual>
            <origin rpy="1.57 0 0" xyz="0 0 0"/>
            <geometry>
                <mesh filename="package://amazon_robot_description/meshes/wheels/right_tire.stl" scale="0.002 0.002 0.002"/>
            </geometry>
            <material name="dark"/>
        </visual>
        <collision>
            <origin rpy="0 0 0" xyz="0 0 0"/>
            <geometry>
                <cylinder length="0.020" radius="0.072"/>
            </geometry>
        </collision>
        <inertial>
            <origin xyz="0 0 0"/>
            <mass value="2.8498940e-02"/>
            <inertia ixx="1.1175580e-05" ixy="-4.2369783e-11" ixz="-5.9381719e-09" iyy="1.1192413e-05" iyz="-1.4400107e-11" izz="2.0712558e-05"/>
        </inertial>
    </link>
    <joint name="caster_back_right_joint" type="fixed">
        <parent link="base_link"/>
        <child link="caster_back_right_link"/>
        <origin rpy="-1.57 0 0" xyz="-0.268 -0.064 -0.016"/>
    </joint>
    <link name="caster_back_right_link">
        <collision>
            <origin rpy="0 0 0" xyz="0 0.001 0"/>
            <geometry>
                <box size="0.060 0.018 0.040"/>
            </geometry>
        </collision>
        <inertial>
            <origin xyz="0 0 0"/>
            <mass value="0.005"/>
            <inertia ixx="0.001" ixy="0.0" ixz="0.0" iyy="0.001" iyz="0.0" izz="0.001"/>
        </inertial>
    </link>
    <joint name="caster_back_left_joint" type="fixed">
        <parent link="base_link"/>
        <child link="caster_back_left_link"/>
        <origin rpy="-1.57 0 0" xyz="-0.268 0.064 -0.016"/>
    </joint>
    <link name="caster_back_left_link">
        <collision>
            <origin rpy="0 0 0" xyz="0 0.001 0"/>
            <geometry>
                <box size="0.060 0.018 0.040"/>
            </geometry>
        </collision>
        <inertial>
            <origin xyz="0 0 0"/>
            <mass value="0.005"/>
            <inertia ixx="0.001" ixy="0.0" ixz="0.0" iyy="0.001" iyz="0.0" izz="0.001"/>
        </inertial>
    </link>
    <joint name="imu_joint" type="fixed">
        <parent link="base_link"/>
        <child link="imu_link"/>
        <origin rpy="0 0 0" xyz="0.0 0 0.136"/>
    </joint>
    <link name="imu_link"/>
    <joint name="lidar_joint" type="fixed">
        <parent link="base_link"/>
        <child link="base_scan"/>
        <origin rpy="0 0 0" xyz="-0.064 0 0.244"/>
    </joint>
    <link name="base_scan">
        <visual>
            <origin rpy="0 0 0" xyz="0 0 0.0"/>
            <geometry>
                <mesh filename="package://amazon_robot_description/meshes/sensors/lds.stl" scale="0.002 0.002 0.002"/>
            </geometry>
            <material name="dark"/>
        </visual>
        <collision>
            <origin rpy="0 0 0" xyz="0.015 0 -0.0065"/>
            <geometry>
                <cylinder length="0.0315" radius="0.055"/>
            </geometry>
        </collision>
        <inertial>
            <mass value="0.114"/>
            <origin xyz="0 0 0"/>
            <inertia ixx="0.001" ixy="0.0" ixz="0.0" iyy="0.001" iyz="0.0" izz="0.001"/>
        </inertial>
    </link>
    <link name="link_platform_mid">
        <origin rpy="0 0 0" xyz="0 0 0.0"/>
        <visual>
            <geometry>
                <box size="0.02 0.02 0.10"/>
            </geometry>
            <material name="blue"/>
        </visual>
        <collision>
            <geometry>
                <box size="0.02 0.02 0.10"/>
            </geometry>
        </collision>
        <inertial>
            <mass value="1"/>
            <inertia ixx="1.0" ixy="0.0" ixz="0.0" iyy="1.0" iyz="0.0" izz="1.0"/>
        </inertial>
    </link>
    <joint name="platform_joint" type="fixed">
        <parent link="base_link"/>
        <child link="link_platform_mid"/>
        <origin rpy="0. 0. 0." xyz="-0.02 0.0 0.30"/>
    </joint>
    <link name="lift_link">
        <origin rpy="0 0 0" xyz="0 0 0.0"/>
        <visual>
            <geometry>
                <box size="0.40 0.40 0.01"/>
            </geometry>
            <material name="red"/>
        </visual>
        <collision>
            <geometry>
                <box size="0.40 0.40 0.01"/>
            </geometry>
        </collision>
        <inertial>
            <mass value="1"/>
            <inertia ixx="1.0" ixy="0.0" ixz="0.0" iyy="1.0" iyz="0.0" izz="1.0"/>
        </inertial>
    </link>
    
    
    <joint name="lift_joint" type="prismatic">
        <parent link="link_platform_mid"/>
        <child link="lift_link"/>
        <axis><use_parent_model_frame>true</use_parent_model_frame><xyz>0 0 1</xyz></axis>
        <calibration rising="0.0"/>
        <dynamics damping="0.0" friction="0.0"/>
        <limit effort="20.0" lower="0.20" upper="0.30" velocity="5.00"/>
        <safety_controller k_velocity="10" k_position="15" soft_lower_limit="-2.0" soft_upper_limit="0.5" />
    </joint>






  <joint name="camera_joint" type="fixed">
    <origin xyz="0.23 0 0.23" rpy="0 0 0"/>
    <parent link="base_link"/>
    <child link="camera_rgb_frame"/>
  </joint>

  <joint name="camera_rgb_joint" type="fixed">
    <origin xyz="0.23 0 0.23" rpy="0 0 0"/>
    <parent link="base_link"/>
    <child link="camera_rgb_frame"/>
  </joint>
  <link name="camera_rgb_frame"/>

  <joint name="camera_rgb_optical_joint" type="fixed">
    <origin xyz="0 0 0" rpy="-1.57 0 -1.57"/>
    <parent link="camera_rgb_frame"/>
    <child link="camera_rgb_optical_frame"/>
  </joint>
  <link name="camera_rgb_optical_frame"/>

  <joint name="camera_depth_joint" type="fixed">
    <origin xyz="0.005 0.028 0.013" rpy="0 0 0"/>
    <!-- <origin xyz="${r200_cam_rgb_px} ${r200_cam_rgb_py + r200_cam_depth_offset} ${r200_cam_rgb_pz}" rpy="0 0 0"/> -->
    <parent link="camera_rgb_frame"/>
    <child link="camera_depth_frame"/>
  </joint>
  <link name="camera_depth_frame"/>

  <joint name="camera_depth_optical_joint" type="fixed">
    <origin xyz="0 0 0" rpy="-1.57 0 -1.57"/>
    <parent link="camera_depth_frame"/>
    <child link="camera_depth_optical_frame"/>
  </joint>
  <link name="camera_depth_optical_frame"/>










</robot>

